<?xml version="1.0" encoding="utf-8"?>
<!-- Author: lnotspotl -->

<!-- This URDF was automatically created by SolidWorks to URDF Exporter! Originally created by Stephen Brawner (brawner@gmail.com)
     Commit Version: 1.5.1-0-g916b5db  Build Version: 1.5.7152.31018
     For more information, please see http://wiki.ros.org/sw_urdf_exporter -->

<robot name="notspot" xmlns:xacro="http://www.ros.org/wiki/xacro">

    <!-- Import all Gazebo-customization elements, including Gazebo colors -->
    <xacro:include filename="$(find open_manipulator_description)/urdf/open_manipulator.gazebo.xacro" />
    <!-- Import Rviz colors -->
    <xacro:include filename="$(find open_manipulator_description)/urdf/materials.xacro" />
  
    <!-- Transmission macro, EffortJointInterface, PositionJointInterface -->
    <xacro:macro name="SimpleTransmission" params="joint n">
      <transmission name="tran${n}">
        <type>transmission_interface/SimpleTransmission</type>
        <joint name="${joint}">
          <hardwareInterface>hardware_interface/EffortJointInterface</hardwareInterface>
        </joint>
        <actuator name="motor${n}">
          <hardwareInterface>hardware_interface/EffortJointInterface</hardwareInterface>
          <mechanicalReduction>1</mechanicalReduction>
        </actuator>
      </transmission>
    </xacro:macro>

  <!-- Maximum torque -->
  <xacro:property name="effort_limit" value="30" />

  <!-- <xacro:include filename="$(find open_manipulator_description)/urdf/open_manipulator_1.xacro"/> -->

  <!-- base_link -->
  <link name="base_link">
    <inertial>
      <origin
        xyz="-0.00048043 9.0814E-05 0.00023409"
        rpy="0 0 0" />
      <mass
        value="0.81776" />
      <inertia
        ixx="0.00058474"
        ixy="-1.0045E-06"
        ixz="1.0886E-08"
        iyy="0.00029699"
        iyz="3.2027E-08"
        izz="0.00063853" />
    </inertial>
    <visual>
      <origin
        xyz="0 0 0"
        rpy="0 0 0" />
      <geometry>
        <mesh
          filename="package://notspot_description/meshes/body_obj.obj" />
      </geometry>
    </visual>
    <collision>
      <origin
        xyz="0 0 0"
        rpy="0 0 0" />
      <geometry>
      	<box size="0.25 0.1285 0.055"/>
      </geometry>
    </collision>
  </link>

  <!-- FR1 -->
  <link name="FR1">
    <inertial>
      <origin
        xyz="0.011092 -0.0032719 0.00019267"
        rpy="0 0 0" />
      <mass
        value="0.15379" />
      <inertia
        ixx="4.474E-05"
        ixy="-1.0746E-05"
        ixz="-1.7651E-07"
        iyy="4.3489E-05"
        iyz="-7.8105E-08"
        izz="6.8646E-05" />
    </inertial>
    <visual>
      <origin
        xyz="0 0 0"
        rpy="0 0 0" />
      <geometry>
        <mesh
          filename="package://notspot_description/meshes/FR1_obj.obj" />
      </geometry>
    </visual>
  </link>

	<!-- FR2 -->
  <link name="FR2">
    <inertial>
      <origin
        xyz="0.038603 -0.0025578 -0.0001752"
        rpy="0 0 0" />
      <mass
        value="0.15106" />
      <inertia
        ixx="2.365E-05"
        ixy="-5.3771E-07"
        ixz="-1.6144E-06"
        iyy="0.00010469"
        iyz="8.3059E-08"
        izz="0.00011187" />
    </inertial>
    <visual>
      <origin
        xyz="0 0 0"
        rpy="0 0 0" />
      <geometry>
        <mesh
          filename="package://notspot_description/meshes/R2_obj.obj" />
      </geometry>
    </visual>
    <collision>
      <origin
        xyz="0.04 0 0"
        rpy="0 1.57075 0" />
      <geometry>
        <cylinder length="0.125" radius="0.014"/>
      </geometry>
    </collision>
  </link>

	<!-- FR3 -->
  <link name="FR3">
    <inertial>
      <origin
        xyz="0.029797 -0.00098828 -9.2749E-05"
        rpy="0 0 0" />
      <mass
        value="0.023372" />
      <inertia
        ixx="6.565E-07"
        ixy="6.8071E-07"
        ixz="-1.0503E-07"
        iyy="2.7257E-05"
        iyz="3.918E-09"
        izz="2.7469E-05" />
    </inertial>
    <visual>
      <origin
        xyz="0 0 0"
        rpy="0 0 0" />
      <geometry>
        <mesh
          filename="package://notspot_description/meshes/R3_obj.obj" />
      </geometry>
    </visual>
    <collision>
      <origin
        xyz="0.045 0 0"
        rpy="0 1.57075 0" />
      <geometry>
        <cylinder length="0.06" radius="0.007"/>
      </geometry>
    </collision>
  </link>

	<!-- FR4 -->
  <link name="FR4">
    <inertial>
      <origin
        xyz="0.00 0 0"
        rpy="0 0 0" />
     <mass
        value="0.0391" />
      <inertia
        ixx="3.7713E-012"
        ixy="0"
        ixz="0"
        iyy="3.5422E-12"
        iyz="0"
        izz="5.443E-012" />
    </inertial>
    <collision>
      <origin
        xyz="0 0 0"
        rpy="0 0 0" />
      <geometry>
        <sphere radius="0.0072"/>
      </geometry>
    </collision>
  </link>

	<!-- FL1 -->
  <link name="FL1">
    <inertial>
      <origin
        xyz="-0.011124 -0.0032814 0.00014476"
        rpy="0 0 0" />
      <mass
        value="0.15334" />
      <inertia
        ixx="4.4732E-05"
        ixy="1.0746E-05"
        ixz="1.7651E-07"
        iyy="4.3482E-05"
        iyz="-7.8105E-08"
        izz="6.8645E-05" />
    </inertial>
    <visual>
      <origin
        xyz="0 0 0"
        rpy="0 0 0" />
      <geometry>
        <mesh
          filename="package://notspot_description/meshes/FL1_obj.obj" />
      </geometry>
    </visual>
  </link>

	<!-- FL2 -->
  <link name="FL2">
    <inertial>
      <origin
        xyz="0.038603 -0.0025578 0.0001752"
        rpy="0 0 0" />
      <mass
        value="0.15106" />
      <inertia
        ixx="2.365E-05"
        ixy="-5.3771E-07"
        ixz="1.6144E-06"
        iyy="0.00010469"
        iyz="-8.306E-08"
        izz="0.00011187" />
    </inertial>
    <visual>
      <origin
        xyz="0 0 0"
        rpy="0 0 0" />
      <geometry>
        <mesh
          filename="package://notspot_description/meshes/L2_obj.obj" />
      </geometry>
    </visual>
    <collision>
      <origin
        xyz="0.04 0 0"
        rpy="0 1.57075 0" />
      <geometry>
        <cylinder length="0.125" radius="0.014"/>
      </geometry>
    </collision>
  </link>

	<!-- FL3 -->
  <link name="FL3">
    <inertial>
      <origin
        xyz="0.029797 -0.0009883 9.2751E-05"
        rpy="0 0 0" />
      <mass
        value="0.023372" />
      <inertia
        ixx="6.565E-07"
        ixy="6.8071E-07"
        ixz="1.0503E-07"
        iyy="2.7257E-05"
        iyz="-3.918E-09"
        izz="2.7469E-05" />
    </inertial>
    <visual>
      <origin
        xyz="0 0 0"
        rpy="0 0 0" />
      <geometry>
        <mesh
          filename="package://notspot_description/meshes/L3_obj.obj" />
      </geometry>
    </visual>
    <collision>
      <origin
        xyz="0.045 0 0"
        rpy="0 1.57075 0" />
      <geometry>
        <cylinder length="0.06" radius="0.007"/>
      </geometry>
    </collision>
  </link>

	<!-- FL4 -->
  <link name="FL4">
    <inertial>
      <origin
        xyz="0.00 0 0"
        rpy="0 0 0" />
     <mass
        value="0.0391" />
      <inertia
        ixx="3.7713E-012"
        ixy="0"
        ixz="0"
        iyy="3.5422E-12"
        iyz="0"
        izz="5.443E-012" />
    </inertial>
    <collision>
      <origin
        xyz="0 0 0"
        rpy="0 0 0" />
      <geometry>
        <sphere radius="0.0072"/>
      </geometry>
    </collision>
  </link>

	<!-- RR1 -->
  <link name="RR1">
    <inertial>
      <origin
        xyz="0.011092 -0.0032719 -0.00019266"
        rpy="0 0 0" />
      <mass
        value="0.15379" />
      <inertia
        ixx="4.474E-05"
        ixy="-1.0746E-05"
        ixz="1.7651E-07"
        iyy="4.3489E-05"
        iyz="7.8105E-08"
        izz="6.8646E-05" />
    </inertial>
    <visual>
      <origin
        xyz="0 0 0"
        rpy="0 0 0" />
      <geometry>
        <mesh
          filename="package://notspot_description/meshes/RR1_obj.obj" />
      </geometry>
    </visual>
  </link>

	<!-- RR2 -->
  <link name="RR2">
    <inertial>
      <origin
        xyz="0.038603 -0.0025578 -0.0001752"
        rpy="0 0 0" />
      <mass
        value="0.15106" />
      <inertia
        ixx="2.365E-05"
        ixy="-5.3771E-07"
        ixz="-1.6144E-06"
        iyy="0.00010469"
        iyz="8.3059E-08"
        izz="0.00011187" />
    </inertial>
    <visual>
      <origin
        xyz="0 0 0"
        rpy="0 0 0" />
      <geometry>
        <mesh
          filename="package://notspot_description/meshes/R2_obj.obj" />
      </geometry>
    </visual>
    <collision>
      <origin
        xyz="0.04 0 0"
        rpy="0 1.57075 0" />
      <geometry>
        <cylinder length="0.125" radius="0.014"/>
      </geometry>
    </collision>
  </link>

	<!-- RR3 -->
  <link name="RR3">
    <inertial>
      <origin
        xyz="0.029797 -0.00098828 -9.2749E-05"
        rpy="0 0 0" />
      <mass
        value="0.023372" />
      <inertia
        ixx="6.565E-07"
        ixy="6.8071E-07"
        ixz="-1.0503E-07"
        iyy="2.7257E-05"
        iyz="3.918E-09"
        izz="2.7469E-05" />
    </inertial>
    <visual>
      <origin
        xyz="0 0 0"
        rpy="0 0 0" />
      <geometry>
        <mesh
          filename="package://notspot_description/meshes/R3_obj.obj" />
      </geometry>
    </visual>
    <collision>
      <origin
        xyz="0.045 0 0"
        rpy="0 1.57075 0" />
      <geometry>
        <cylinder length="0.06" radius="0.007"/>
      </geometry>
    </collision>
  </link>

	<!-- RR4 -->
  <link name="RR4">
    <inertial>
      <origin
        xyz="0.00 0 0"
        rpy="0 0 0" />
     <mass
        value="0.0391" />
      <inertia
        ixx="3.7713E-012"
        ixy="0"
        ixz="0"
        iyy="3.5422E-12"
        iyz="0"
        izz="5.443E-012" />
    </inertial>
    <collision>
      <origin
        xyz="0 0 0"
        rpy="0 0 0" />
      <geometry>
        <sphere radius="0.0072"/>
      </geometry>
    </collision>
  </link>

	<!-- RL1 -->
  <link name="RL1">
    <inertial>
      <origin
        xyz="-0.011092 -0.0032719 -0.00019266"
        rpy="0 0 0" />
      <mass
        value="0.15379" />
      <inertia
        ixx="4.474E-05"
        ixy="1.0746E-05"
        ixz="-1.7651E-07"
        iyy="4.3489E-05"
        iyz="7.8105E-08"
        izz="6.8646E-05" />
    </inertial>
    <visual>
      <origin
        xyz="0 0 0"
        rpy="0 0 0" />
      <geometry>
        <mesh
          filename="package://notspot_description/meshes/RL1_obj.obj" />
      </geometry>
    </visual>
  </link>
  
	<!-- RL2 -->
  <link name="RL2">
    <inertial>
      <origin
        xyz="0.038603 -0.0025578 0.0001752"
        rpy="0 0 0" />
      <mass
        value="0.15106" />
      <inertia
        ixx="2.365E-05"
        ixy="-5.3771E-07"
        ixz="1.6144E-06"
        iyy="0.00010469"
        iyz="-8.306E-08"
        izz="0.00011187" />
    </inertial>
    <visual>
      <origin
        xyz="0 0 0"
        rpy="0 0 0" />
      <geometry>
        <mesh
          filename="package://notspot_description/meshes/L2_obj.obj" />
      </geometry>
    </visual>
    <collision>
      <origin
        xyz="0.04 0 0"
        rpy="0 1.57075 0" />
      <geometry>
        <cylinder length="0.125" radius="0.014"/>
      </geometry>
    </collision>
  </link>

	<!-- RL3 -->
  <link name="RL3">
    <inertial>
      <origin
        xyz="0.029797 -0.0009883 9.2751E-05"
        rpy="0 0 0" />
      <mass
        value="0.023372" />
      <inertia
        ixx="6.565E-07"
        ixy="6.8071E-07"
        ixz="1.0503E-07"
        iyy="2.7257E-05"
        iyz="-3.918E-09"
        izz="2.7469E-05" />
    </inertial>
    <visual>
      <origin
        xyz="0 0 0"
        rpy="0 0 0" />
      <geometry>
        <mesh
          filename="package://notspot_description/meshes/L3_obj.obj" />
      </geometry>
    </visual>
    <collision>
      <origin
        xyz="0.045 0 0"
        rpy="0 1.57075 0" />
      <geometry>
        <cylinder length="0.06" radius="0.007"/>
      </geometry>
    </collision>
  </link>

	<!-- RL4 -->
  <link name="RL4">
    <inertial>
      <origin
        xyz="0.00 0 0"
        rpy="0 0 0" />
     <mass
        value="0.0391" />
      <inertia
        ixx="3.7713E-012"
        ixy="0"
        ixz="0"
        iyy="3.5422E-12"
        iyz="0"
        izz="5.443E-012" />
    </inertial>
    <collision>
      <origin
        xyz="0 0 0"
        rpy="0 0 0" />
      <geometry>
        <sphere radius="0.0072"/>
      </geometry>
    </collision>
  </link>

<!-- JOINTS -->

  <joint name="FR1_joint"
    type="revolute">
    <origin
      xyz="0.0954 -0.04 0"
      rpy="1.5708 0 -1.5708" />
    <parent
      link="base_link" />
    <child
      link="FR1" />
    <axis
      xyz="0 0 1" />
    <limit
      lower="-3"
      upper="3"
      effort="${effort_limit}"
      velocity="3" />
  </joint>


  <joint name="FR2_joint"
    type="revolute">
    <origin
      xyz="0.0469 0 0"
      rpy="1.5708 0 -1.5708" />
    <parent
      link="FR1" />
    <child
      link="FR2" />
    <axis
      xyz="0 0 1" />
    <limit
      lower="-3"
      upper="3"
      effort="${effort_limit}"
      velocity="3" />
  </joint>

  <joint name="FR3_joint"
    type="revolute">
    <origin
      xyz="0.1 0 0"
      rpy="0 0 0" />
    <parent
      link="FR2" />
    <child
      link="FR3" />
    <axis
      xyz="0 0 1" />
    <limit
      lower="-3"
      upper="3"
      effort="${effort_limit}"
      velocity="3" />
  </joint>

  <joint name="FR4_joint"
    type="fixed">
    <origin
      xyz="0.094333 0 0"
      rpy="0 0 0" />
    <parent
      link="FR3" />
    <child
      link="FR4" />
    <axis
      xyz="0 0 0" />
  </joint>

  <joint name="FL1_joint"
    type="revolute">
    <origin
      xyz="0.0954 0.04 0"
      rpy="1.5708 0 -1.5708" />
    <parent
      link="base_link" />
    <child
      link="FL1" />
    <axis
      xyz="0 0 1" />
    <limit
      lower="-3"
      upper="3"
      effort="${effort_limit}"
      velocity="3" />
  </joint>

  <joint name="FL2_joint"
    type="revolute">
    <origin
      xyz="-0.0469 0 0"
      rpy="1.5708 0 -1.5708" />
    <parent
      link="FL1" />
    <child
      link="FL2" />
    <axis
      xyz="0 0 1" />
    <limit
      lower="-3"
      upper="3"
      effort="${effort_limit}"
      velocity="3" />
  </joint>

  <joint name="FL3_joint"
    type="revolute">
    <origin
      xyz="0.1 0 0"
      rpy="0 0 0" />
    <parent
      link="FL2" />
    <child
      link="FL3" />
    <axis
      xyz="0 0 1" />
    <limit
      lower="-3"
      upper="3"
      effort="${effort_limit}"
      velocity="3" />
  </joint>

  <joint name="FL4_joint"
    type="fixed">
    <origin
      xyz="0.094333 0 0"
      rpy="0 0 0" />
    <parent
      link="FL3" />
    <child
      link="FL4" />
    <axis
      xyz="0 0 0" />
  </joint>

  <joint name="RR1_joint"
    type="revolute">
    <origin
      xyz="-0.0954 -0.04 0"
      rpy="1.5708 0 -1.5708" />
    <parent
      link="base_link" />
    <child
      link="RR1" />
    <axis
      xyz="0 0 1" />
    <limit
      lower="-3"
      upper="3"
      effort="${effort_limit}"
      velocity="3" />
  </joint>

  <joint name="RR2_joint"
    type="revolute">
    <origin
      xyz="0.0469 0 0"
      rpy="1.5708 0 -1.5708" />
    <parent
      link="RR1" />
    <child
      link="RR2" />
    <axis
      xyz="0 0 1" />
    <limit
      lower="-3"
      upper="3"
      effort="${effort_limit}"
      velocity="3" />
  </joint>

  <joint name="RR3_joint"
    type="revolute">
    <origin
      xyz="0.1 0 0"
      rpy="0 0 0" />
    <parent
      link="RR2" />
    <child
      link="RR3" />
    <axis
      xyz="0 0 1" />
    <limit
      lower="-3"
      upper="3"
      effort="${effort_limit}"
      velocity="3" />
  </joint>

  <joint name="RR4_joint"
    type="fixed">
    <origin
      xyz="0.094333 0 0"
      rpy="0 0 0" />
    <parent
      link="RR3" />
    <child
      link="RR4" />
    <axis
      xyz="0 0 0" />
  </joint>

  <joint name="RL1_joint"
    type="revolute">
    <origin
      xyz="-0.0954 0.04 0"
      rpy="1.5708 0 -1.5708" />
    <parent
      link="base_link" />
    <child
      link="RL1" />
    <axis
      xyz="0 0 1" />
    <limit
      lower="-3"
      upper="3"
      effort="${effort_limit}"
      velocity="3" />
  </joint>

  <joint name="RL2_joint"
    type="revolute">
    <origin
      xyz="-0.0469 0 0"
      rpy="1.5708 0 -1.5708" />
    <parent
      link="RL1" />
    <child
      link="RL2" />
    <axis
      xyz="0 0 1" />
    <limit
      lower="-3"
      upper="3"
      effort="${effort_limit}"
      velocity="3" />
  </joint>

  <joint name="RL3_joint"
    type="revolute">
    <origin
      xyz="0.1 0 0"
      rpy="0 0 0" />
    <parent
      link="RL2" />
    <child
      link="RL3" />
    <axis
      xyz="0 0 1" />
    <limit
      lower="-3"
      upper="3"
      effort="${effort_limit}"
      velocity="3" />
  </joint>

  <joint name="RL4_joint"
    type="fixed">
    <origin
      xyz="0.094333 0 0"
      rpy="0 0 0" />
    <parent
      link="RL3" />
    <child
      link="RL4" />
    <axis
      xyz="0 0 0" />
  </joint>

  <!-- ROS control plugin -->
  <gazebo>
    <plugin name="gazebo_ros_control" filename="libgazebo_ros_control.so">
      <robotNamespace>notspot_controller</robotNamespace>
    </plugin>
  </gazebo>

  <!-- IMU sensor -->
  <gazebo reference="base_link">
    <gravity>true</gravity>
    <sensor name="imu_sensor" type="imu">
      <always_on>true</always_on>
      <update_rate>100</update_rate>
      <visualize>true</visualize>
      <topic>__default_topic__</topic>
      <plugin filename="libgazebo_ros_imu_sensor.so" name="imu_plugin">
        <topicName>notspot_imu/base_link_orientation</topicName>
        <bodyName>imu_link</bodyName>
        <updateRateHZ>15.0</updateRateHZ>
        <gaussianNoise>0.0</gaussianNoise>
        <xyzOffset>0 0 0</xyzOffset>
        <rpyOffset>0 0 0</rpyOffset>
        <frameName>base_link</frameName>
        <initialOrientationAsReference>false</initialOrientationAsReference>
      </plugin>
      <pose>0 0 0 0 0 0</pose>
    </sensor>
  </gazebo>

  <!-- Joint state publisher plugin -->
  <gazebo>
    <plugin name="joint_state_publisher" filename="libgazebo_ros_joint_state_publisher.so">
        <robotNamespace>notspot_gazebo</robotNamespace>
        <jointName>FR1_joint, FR2_joint, FR3_joint, FL1_joint, FL2_joint,
                   FL3_joint, RR1_joint, RR2_joint, RR3_joint, RL1_joint,
                   RL2_joint, RL3_joint</jointName>
        <updateRate>100</updateRate>
    </plugin>
  </gazebo>

  <!-- Transmission -->
  <transmission name="tran1">
    <type>transmission_interface/SimpleTransmission</type>
    <joint name="FR1_joint">
      <hardwareInterface>hardware_interface/EffortJointInterface</hardwareInterface>
    </joint>
    <actuator name="motor1">
    <hardwareInterface>hardware_interface/EffortJointInterface</hardwareInterface>
    <mechanicalReduction>5</mechanicalReduction>
    </actuator>
  </transmission>

  <transmission name="tran2">
    <type>transmission_interface/SimpleTransmission</type>
    <joint name="FR2_joint">
      <hardwareInterface>hardware_interface/EffortJointInterface</hardwareInterface>
    </joint>
    <actuator name="motor2">
    <hardwareInterface>hardware_interface/EffortJointInterface</hardwareInterface>
    <mechanicalReduction>5</mechanicalReduction>
    </actuator>
  </transmission>

  <transmission name="tran3">
    <type>transmission_interface/SimpleTransmission</type>
    <joint name="FR3_joint">
      <hardwareInterface>hardware_interface/EffortJointInterface</hardwareInterface>
    </joint>
    <actuator name="motor3">
    <hardwareInterface>hardware_interface/EffortJointInterface</hardwareInterface>
    <mechanicalReduction>5</mechanicalReduction>
    </actuator>
  </transmission>

  <transmission name="tran4">
    <type>transmission_interface/SimpleTransmission</type>
    <joint name="FL1_joint">
      <hardwareInterface>hardware_interface/EffortJointInterface</hardwareInterface>
    </joint>
    <actuator name="motor4">
    <hardwareInterface>hardware_interface/EffortJointInterface</hardwareInterface>
    <mechanicalReduction>5</mechanicalReduction>
    </actuator>
  </transmission>

  <transmission name="tran5">
    <type>transmission_interface/SimpleTransmission</type>
    <joint name="FL2_joint">
      <hardwareInterface>hardware_interface/EffortJointInterface</hardwareInterface>
    </joint>
    <actuator name="motor5">
    <hardwareInterface>hardware_interface/EffortJointInterface</hardwareInterface>
    <mechanicalReduction>5</mechanicalReduction>
    </actuator>
  </transmission>

  <transmission name="tran6">
    <type>transmission_interface/SimpleTransmission</type>
    <joint name="FL3_joint">
      <hardwareInterface>hardware_interface/EffortJointInterface</hardwareInterface>
    </joint>
    <actuator name="motor6">
    <hardwareInterface>hardware_interface/EffortJointInterface</hardwareInterface>
    <mechanicalReduction>5</mechanicalReduction>
    </actuator>
  </transmission>

  <transmission name="tran7">
    <type>transmission_interface/SimpleTransmission</type>
    <joint name="RR1_joint">
      <hardwareInterface>hardware_interface/EffortJointInterface</hardwareInterface>
    </joint>
    <actuator name="motor7">
    <hardwareInterface>hardware_interface/EffortJointInterface</hardwareInterface>
    <mechanicalReduction>5</mechanicalReduction>
    </actuator>
  </transmission>

  <transmission name="tran8">
    <type>transmission_interface/SimpleTransmission</type>
    <joint name="RR2_joint">
      <hardwareInterface>hardware_interface/EffortJointInterface</hardwareInterface>
    </joint>
    <actuator name="motor8">
    <hardwareInterface>hardware_interface/EffortJointInterface</hardwareInterface>
    <mechanicalReduction>5</mechanicalReduction>
    </actuator>
  </transmission>

  <transmission name="tran9">
    <type>transmission_interface/SimpleTransmission</type>
    <joint name="RR3_joint">
      <hardwareInterface>hardware_interface/EffortJointInterface</hardwareInterface>
    </joint>
    <actuator name="motor9">
    <hardwareInterface>hardware_interface/EffortJointInterface</hardwareInterface>
    <mechanicalReduction>5</mechanicalReduction>
    </actuator>
  </transmission>

  <transmission name="tran10">
    <type>transmission_interface/SimpleTransmission</type>
    <joint name="RL1_joint">
      <hardwareInterface>hardware_interface/EffortJointInterface</hardwareInterface>
    </joint>
    <actuator name="motor10">
    <hardwareInterface>hardware_interface/EffortJointInterface</hardwareInterface>
    <mechanicalReduction>5</mechanicalReduction>
    </actuator>
  </transmission>

  <transmission name="tran11">
    <type>transmission_interface/SimpleTransmission</type>
    <joint name="RL2_joint">
      <hardwareInterface>hardware_interface/EffortJointInterface</hardwareInterface>
    </joint>
    <actuator name="motor11">
    <hardwareInterface>hardware_interface/EffortJointInterface</hardwareInterface>
    <mechanicalReduction>5</mechanicalReduction>
    </actuator>
  </transmission>

  <transmission name="tran12">
    <type>transmission_interface/SimpleTransmission</type>
    <joint name="RL3_joint">
      <hardwareInterface>hardware_interface/EffortJointInterface</hardwareInterface>
    </joint>
    <actuator name="motor12">
    <hardwareInterface>hardware_interface/EffortJointInterface</hardwareInterface>
    <mechanicalReduction>5</mechanicalReduction>
    </actuator>
  </transmission>

  <!-- FR4 friction -->
  <gazebo reference="FR4">
    <mu1>1.0</mu1>
    <mu2>1.0</mu2>
    <minDepth>0.0002</minDepth>
    <kp  value="1000000.0"/>
    <kd  value="100.0"/>
  </gazebo>

  <!-- FL4 friction -->
  <gazebo reference="FL4">
    <mu1>1.0</mu1>
    <mu2>1.0</mu2>
    <minDepth>0.0002</minDepth>
    <kp  value="1000000.0"/>
    <kd  value="100.0"/>
  </gazebo>

  <!-- RR4 friction -->
  <gazebo reference="RR4">
    <mu1>1.0</mu1>
    <mu2>1.0</mu2>
    <minDepth>0.0002</minDepth>
    <kp  value="1000000.0"/>
    <kd  value="100.0"/>
  </gazebo>

  <!-- RL4 friction -->
  <gazebo reference="RL4">
    <mu1>1.0</mu1>
    <mu2>1.0</mu2>
    <minDepth>0.0002</minDepth>
    <kp  value="1000000.0"/>
    <kd  value="100.0"/>
  </gazebo>

  <!-- Robotic arm -->
    <!-- World fixed joint-->
    <joint name="world_fixed" type="fixed">
      <origin xyz="0.052 0.0 0" rpy="0 0 0"/>
      <parent link="base_link"/>
      <child link="link1"/>
    </joint>
  
    <!-- Link 1 -->
    <link name="link1">
      <visual>
        <origin xyz="0 0 0" rpy="0 0 0"/>
        <geometry>
          <mesh filename="package://open_manipulator_description/meshes/chain_link1.stl" scale="0.001 0.001 0.001"/>
        </geometry>
        <material name="grey"/>
      </visual>
  
      <collision>
        <origin xyz="0 0 0" rpy="0 0 0"/>
        <geometry>
          <mesh filename="package://open_manipulator_description/meshes/chain_link1.stl" scale="0.001 0.001 0.001"/>
        </geometry>
      </collision>
  
  <!--    <inertial>
        <origin xyz="0 0 0" />
        <mass value="0.082" />
        <inertia ixx="0.1" ixy="0.0" ixz="0.0"
                 iyy="0.1" iyz="0.0"
                 izz="0.1" />
      </inertial>-->
  
       <inertial>
        <origin xyz="3.0876154e-04 0.0000000e+00 -1.2176461e-04" />
        <mass value="7.9119962e-02" />
        <inertia ixx="1.2505234e-05" ixy="0.0" ixz="-1.7855208e-07"
                 iyy="2.1898364e-05" iyz="0.0"
                 izz="1.9267361e-05" />
      </inertial>
    </link>
  
    <!-- Joint 1 -->
    <joint name="joint1" type="revolute">
      <parent link="link1"/>
      <child link="link2"/>
      <origin xyz="0.012 0.0 0.017" rpy="0 0 1.57"/>
      <axis xyz="0 0 1"/>
      <limit velocity="4.8" effort="1" lower="${-pi*0.9}" upper="${pi*0.9}" />
    </joint>
  
    <!-- Transmission 1 -->
    <xacro:SimpleTransmission n="1" joint="joint1" />
  
    <!--  Link 2 -->
    <link name="link2">
      <visual>
        <origin xyz="0 0 0.019" rpy="0 0 0"/>
        <geometry>
          <mesh filename="package://open_manipulator_description/meshes/chain_link2.stl" scale="0.001 0.001 0.001"/>
        </geometry>
        <material name="grey"/>
      </visual>
  
      <collision>
        <origin xyz="0 0 0.019" rpy="0 0 0"/>
        <geometry>
          <mesh filename="package://open_manipulator_description/meshes/chain_link2.stl" scale="0.001 0.001 0.001"/>
        </geometry>
      </collision>
  
  <!--    <inertial>
        <origin xyz="0 0 0" />
        <mass value="0.098" />
        <inertia ixx="0.1" ixy="0.0" ixz="0.0"
                 iyy="0.1" iyz="0.0"
                 izz="0.1" />
      </inertial>-->
  
       <inertial>
        <origin xyz="-3.0184870e-04 5.4043684e-04 ${0.018 + 2.9433464e-02}" />
        <mass value="9.8406837e-02" />
        <inertia ixx="3.4543422e-05" ixy="-1.6031095e-08" ixz="-3.8375155e-07"
                 iyy="3.2689329e-05" iyz="2.8511935e-08"
                 izz="1.8850320e-05" />
      </inertial>
    </link>
  
    <!--  Joint 2 -->
    <joint name="joint2" type="revolute">
      <parent link="link2"/>
      <child link="link3"/>
      <origin xyz="0.0 0.0 0.0595" rpy="0 0 0"/>
      <axis xyz="0 1 0"/>
      <limit velocity="4.8" effort="1" lower="${-pi*0.57}" upper="${pi*0.5}" />
    </joint>
  
    <!-- Transmission 2 -->
    <xacro:SimpleTransmission n="2" joint="joint2" />
  
    <!--  Link 3 -->
    <link name="link3">
      <visual>
        <origin xyz="0 0 0" rpy="0 0 0"/>
        <geometry>
          <mesh filename="package://open_manipulator_description/meshes/chain_link3.stl" scale="0.001 0.001 0.001"/>
        </geometry>
        <material name="grey"/>
      </visual>
  
      <collision>
        <origin xyz="0 0 0" rpy="0 0 0"/>
        <geometry>
          <mesh filename="package://open_manipulator_description/meshes/chain_link3.stl" scale="0.001 0.001 0.001"/>
        </geometry>
      </collision>
  
  <!--    <inertial>
        <origin xyz="0 0 0" />
        <mass value="0.136" />
        <inertia ixx="0.1" ixy="0.0" ixz="0.0"
                 iyy="0.1" iyz="0.0"
                 izz="0.1" />
      </inertial>-->
  
       <inertial>
        <origin xyz="1.0308393e-02 3.7743363e-04 1.0170197e-01" />
        <mass value="1.3850917e-01" />
        <inertia ixx="3.3055381e-04" ixy="-9.7940978e-08" ixz="-3.8505711e-05"
                 iyy="3.4290447e-04" iyz="-1.5717516e-06"
                 izz="6.0346498e-05" />
      </inertial>
    </link>
  
    <!--  Joint 3 -->
    <joint name="joint3" type="revolute">
      <parent link="link3"/>
      <child link="link4"/>
      <origin xyz="0.024 0 0.128" rpy="0 0 0"/>
      <!-- <origin xyz="0 0 0.128" rpy="0 0 0"/> -->
      <axis xyz="0 1 0"/>
      <limit velocity="4.8" effort="1" lower="${-pi*0.3}" upper="${pi*0.44}" />
    </joint>
  
    <!-- Transmission 3 -->
    <xacro:SimpleTransmission n="3" joint="joint3" />
  
    <!--  Link 4 -->
    <link name="link4">
      <visual>
        <origin xyz="0 0 0" rpy="0 0 0"/>
        <geometry>
          <mesh filename="package://open_manipulator_description/meshes/chain_link4.stl" scale="0.001 0.001 0.001"/>
        </geometry>
        <material name="grey"/>
      </visual>
  
      <collision>
        <origin xyz="0 0 0" rpy="0 0 0"/>
        <geometry>
          <mesh filename="package://open_manipulator_description/meshes/chain_link4.stl" scale="0.001 0.001 0.001"/>
        </geometry>
      </collision>
  
  <!--    <inertial>
        <origin xyz="0 0 0" />
        <mass value="0.131" />
        <inertia ixx="0.1" ixy="0.0" ixz="0.0"
                 iyy="0.1" iyz="0.0"
                 izz="0.1" />
      </inertial>-->
  
       <inertial>
        <origin xyz="9.0909590e-02 3.8929816e-04 2.2413279e-04" />
        <mass value="1.3274562e-01" />
        <inertia ixx="3.0654178e-05" ixy="-1.2764155e-06" ixz="-2.6874417e-07"
                 iyy="2.4230292e-04" iyz="1.1559550e-08"
                 izz="2.5155057e-04" />
      </inertial>
    </link>
  
    <!--  Joint 4 -->
    <joint name="joint4" type="revolute">
      <parent link="link4"/>
      <child link="link5"/>
      <origin xyz="0.124 0.0 0.0" rpy="0 0 0"/>
      <axis xyz="0 1 0"/>
      <limit velocity="4.8" effort="1" lower="${-pi*0.57}" upper="${pi*0.65}" />
    </joint>
  
    <!-- Transmission 4 -->
    <xacro:SimpleTransmission n="4" joint="joint4" />
  
    <!--  Link 5 -->
    <link name="link5">
      <visual>
        <origin xyz="0 0 0" rpy="0 0 0"/>
        <geometry>
          <mesh filename="package://open_manipulator_description/meshes/chain_link5.stl" scale="0.001 0.001 0.001"/>
        </geometry>
        <material name="grey"/>
      </visual>
  
      <collision>
        <origin xyz="0 0 0" rpy="0 0 0"/>
        <geometry>
          <mesh filename="package://open_manipulator_description/meshes/chain_link5.stl" scale="0.001 0.001 0.001"/>
        </geometry>
      </collision>
  
  <!--    <inertial>
        <origin xyz="0 0 0" />
        <mass value="0.141" />
        <inertia ixx="0.1" ixy="0.0" ixz="0.0"
                 iyy="0.1" iyz="0.0"
                 izz="0.1" />
      </inertial>-->
  
       <inertial>
        <origin xyz="4.4206755e-02 3.6839985e-07 8.9142216e-03" />
        <mass value="1.4327573e-01" />
        <inertia ixx="8.0870749e-05" ixy="0.0" ixz="-1.0157896e-06"
                 iyy="7.5980465e-05" iyz="0.0"
                 izz="9.3127351e-05" />
      </inertial>
    </link>
  
    <!--  Gripper link -->
    <link name="gripper_link">
      <visual>
        <origin xyz="0.0 0.0 0" rpy="0 0 0"/>
        <geometry>
          <mesh filename="package://open_manipulator_description/meshes/chain_link_grip_l.stl" scale="0.001 0.001 0.001"/>
        </geometry>
        <material name="grey"/>
      </visual>
  
      <collision>
        <origin xyz="0.0 0.0 0" rpy="0 0 0"/>
        <geometry>
          <mesh filename="package://open_manipulator_description/meshes/chain_link_grip_l.stl" scale="0.001 0.001 0.001"/>
        </geometry>
      </collision>
  
      <inertial>
        <origin xyz="0 0 0" />
        <mass value="0.017" />
        <inertia ixx="1.0e-03" ixy="0.0" ixz="0.0"
                 iyy="1.0e-03" iyz="0.0"
                 izz="1.0e-03" />
      </inertial>
  
  <!--     <inertial>
        <origin xyz="${0.028 + 8.3720668e-03} ${0.0246 + 9.9696160e-03} -4.2836895e-07" />
        <mass value="3.2218127e-02" />
        <inertia ixx="9.5568826e-06" ixy="2.8424644e-06" ixz="-3.2829197e-10"
                 iyy="2.2552871e-05" iyz="-3.1463634e-10"
                 izz="1.7605306e-05" />
      </inertial>-->
    </link>
  
    <!--  Gripper joint -->
    <joint name="gripper" type="prismatic">
      <parent link="link5"/>
      <child link="gripper_link"/>
      <origin xyz="0.0817 0.021 0.0" rpy="0 0 0"/>
      <axis xyz="0 1 0"/>
      <limit velocity="4.8" effort="1" lower="-0.010" upper="0.019" />
    </joint>
  
    <!-- Transmission 5 -->
    <xacro:SimpleTransmission n="5" joint="gripper" />
  
    <!--  Gripper link sub -->
    <link name="gripper_link_sub">
      <visual>
        <origin xyz="0.0 -0.0 0" rpy="0 0 0"/>
        <geometry>
          <mesh filename="package://open_manipulator_description/meshes/chain_link_grip_r.stl" scale="0.001 0.001 0.001"/>
        </geometry>
        <material name="grey"/>
      </visual>
  
      <collision>
        <origin xyz="0.0 -0.0 0" rpy="0 0 0"/>
        <geometry>
          <mesh filename="package://open_manipulator_description/meshes/chain_link_grip_r.stl" scale="0.001 0.001 0.001"/>
        </geometry>
      </collision>
  
      <inertial>
        <origin xyz="0 0 0" />
        <mass value="0.017" />
        <inertia ixx="1.0e-03" ixy="0.0" ixz="0.0"
                 iyy="1.0e-03" iyz="0.0"
                 izz="1.0e-03" />
      </inertial>
  
  <!--     <inertial>
        <origin xyz="${0.028 + 8.3720668e-03} ${-0.0246 - 9.9696160e-03} -4.2836895e-07" />
        <mass value="3.2218127e-02" />
        <inertia ixx="9.5568826e-06" ixy="2.8424644e-06" ixz="-3.2829197e-10"
                 iyy="2.2552871e-05" iyz="-3.1463634e-10"
                 izz="1.7605306e-05" />
      </inertial>-->
    </link>
  
    <!--  Gripper joint sub -->
    <joint name="gripper_sub" type="prismatic">
      <parent link="link5"/>
      <child link="gripper_link_sub"/>
      <origin xyz="0.0817 -0.021 0" rpy="0 0 0"/>
      <axis xyz="0 -1 0"/>
      <limit velocity="4.8" effort="1" lower="-0.010" upper="0.019" />
      <mimic joint="gripper" multiplier="1"/>
    </joint>
  
    <!-- Transmission 6 -->
    <xacro:SimpleTransmission n="6" joint="gripper_sub" />
  
    <!-- end effector joint -->
    <joint name="end_effector_joint" type="fixed">
      <origin xyz="0.126 0.0 0.0" rpy="0 0 0"/>
      <parent link="link5"/>
      <child link="end_effector_link"/>
    </joint>
  
    <!-- end effector link -->
    <link name="end_effector_link">
      <visual>
        <origin xyz="0 0 0" rpy="0 0 0"/>
        <geometry>
          <box size="0.01 0.01 0.01" />
        </geometry>
        <material name="red"/>
       </visual>
  
      <inertial>
        <origin xyz="0.0 0.0 0.0" rpy="0 0 0"/>
        <mass value="0.001"/>
        <inertia ixx="1.0e-06" ixy="0.0" ixz="0.0" iyy="1.0e-06" iyz="0.0" izz="1.0e-06" />
      </inertial>
    </link>

    <link name="tray">
      <visual>
        <origin xyz="0.0 -0.0 0" rpy="0 0 0"/>
        <geometry>
          <mesh filename="package://open_manipulator_description/meshes/tray.stl" scale="0.0004 0.0004 0.0004"/>
        </geometry>
        <material name= "yellow" >
          <color rgba="0.909803922 0.0.6784331373 0.137254902 0.0" />
        </material>
        <!-- <material name="grey"/> -->
      </visual>
  
      <collision>
        <origin xyz="0.0 -0.0 0" rpy="0 0 0"/>
        <geometry>
          <mesh filename="package://open_manipulator_description/meshes/tray.stl" scale="0.0004 0.0004 0.0004"/>
        </geometry>
      </collision>
  
      <inertial>
        <origin xyz="0 0 0" />
        <mass value="0.017" />
        <inertia ixx="1.0e-03" ixy="0.0" ixz="0.0"
                 iyy="1.0e-03" iyz="0.0"
                 izz="1.0e-03" />
      </inertial>
    </link>

    <joint name="joint_tray" type="fixed">
      <origin xyz="-0.08 0.0 -0.095" rpy="0.0 0.0 1.5708"/>
      <parent link="base_link"/>
      <child link="tray"/>
      <axis xyz="0.0 0.0 0.0"/>
    </joint>

    <gazebo reference="link1">
      <material>
        <color rgba="0.75 0.75 0.75 1.0" />
      </material>
    </gazebo>
    
    <gazebo reference="link2">
      <material>Gazebo/Grey</material>
    </gazebo>
    
    <gazebo reference="link3">
      <material>Gazebo/Black</material>
    </gazebo>
    
    <gazebo reference="link4">
      <material>Gazebo/Black</material>
    </gazebo>
    
    <gazebo reference="link5">
      <material>Gazebo/Black</material>
    </gazebo>

    <gazebo reference="gripper_link">
      <material>Gazebo/Blue</material>
      <mu1>2</mu1>
      <mu2>2</mu2>
    </gazebo>

    <gazebo reference="gripper_link_sub">
      <material>Gazebo/Blue</material>
      <mu1>2</mu1>
      <mu2>2</mu2>
    </gazebo>

    <gazebo reference="tray">
      <!-- <material name= "yellow" >
        <color rgba="0.909803922 0.0.6784331373 0.137254902 1.0" />
      </material> -->
      <material>Gazebo/Grey</material>

    </gazebo>

</robot>